Workbook

Sheet DESPLEGABLES
A1: ESCUELA | D1: MODALIDAD DE EXAMEN | G1: STATUS DE DOCUMENTOS | J1: CAMPAÑAS | L1: EVENTOS
A2: COMUNICACIONES | D2: ORDINARIO | G2: PENDIENTE TODO | J2: Open Day 1 | L2: Open Day 1
A3: TURISMO | D3: TERCIO SUPERIOR | G3: ENTREGADO-COMPLETO | J3: Open Day 2 | L3: Open Day 2
A4: PSICOLOGIA | D4: EXAMEN DIGITAL | G4: PEND. CERTIFICADO | J4: Open Day 3 | L4: Open Day 3
D5: COMPLEMENTACIÓN ACADÉMICA | G5: PEND. DNI | J5: Open Day 4 | L5: Open Day 4
D6: PRIMERA ALTERNATIVA | G6: PEND. DECLARACION JURADA | J6: Taller Vivencial 1 | L6: Taller Vivencial 1
A7: RESPUESTA | D7: TRASLADA INTERNO | J7: Taller Vivencial 2 | L7: Taller Vivencial 2
A8: SI | D8: TRASLADO EXTERNO | J8: Taller Vivencial 3 | L8: Taller Vivencial 3
A9: NO | D9: CEA | J9: Visita Guiada | L9: Taller Vivencial 4
A10: EN PROCESO | D10: PA | J10: Examen Digital | L10: Taller Vivencial 5
J11: Admisión regular | L11: Taller Vivencial 6
J12: Complementación académica | L12: Taller Vivencial 7
L13: Visita Guiada
G14: ÁREA QUE ATIENDE
D15: ORIGEN DE DATA | G15: DIREC. COMUNICACIONES
A16: SEMESTRE | D16: BASE ANTIGUA | G16: DIREC. TURISMO
A17: 2025-II | D17: PAUTA DIGITAL | G17: DIREC. PSICOLOGIA
A18: 2026-I | D18: EVENTO PRESENCIAL | G18: COORDINACIÓN
D19: WEB | G19: ORA
A20: MODALIDAD | D20: CENTRAL | G20: TESORERÍA | J20: ESTADO DEL POSTULANTE
A21: REACTUALIZACIÓN DE MATRÍCULA | D21: COUNTER | G21: OTI | J21: 4to
A22: REGULAR | D22: EXPOUNIVERSIDAD | G22: COMERCIAL | J22: 5to
A23: DEFICIENCIA ACADÉMICA | D23: VISITA A COLEGIOS | J23: Terminó el colegio
A24: RESERVA DE MATRÍCULA | J24: Tiene título técnico
G25: CONTACTO I
A26: RETIRO DE CICLO | D26: ASESORES | G26: MOSTRÓ INTERÉS | J26: No tiene título técnico
A27: INGRESANTE | D27: MELISA ARCIGA | G27: SE ENVIÓ INFORMACIÓN
D28: SHEYLA PEÑA | G28: NO CONTESTA
D29: PYA PINTO | G29: INCONTACTABLE
A30: STATUS ACADÉMICO | D30: LILYA ESPINOZA | G30: EVALUANDO OPCIONES
A31: NO INSCRITO | D31: ESTRELLA VERGARA | G31: SELECCIONÓ OTRA UNIVERSIDAD
A32: INSCRITO | G32: OTROS
A33: ADMITIDO
A34: MATRICULADO | D34: SEDE
D35: SURQUILLO
A36: TIPO DE EXAMEN | D36: SANTA ANITA
A37: VIRTUAL | D37: COMAS
A38: PRESENCIAL
D40: PAGO INSCRIPCION
A41: STATUS EXAMEN | D41: SI - EXAMEN PRESENCIAL
...

Sheet BASE DE DATOS
A1: DNI | B1: NOMBRES | C1: CELULAR | D1: CORREO | E1: COLEGIO DE PROCEDENCIA | F1: MODALIDAD | G1: ESCUELA | H1: ORIGEN | I1: SEDE | J1: SEMESTRE | K1: CAMPAÑA | L1: EVENTO | M1: FECHA DE INGRESO DE LEAD | N1: CONTACTO I | O1: CONTACTO II | P1: CONTACTO III | Q1: ¿PAGÓ DERECHO DE INSCRIPCIÓN? | R1: STATUS ACADÉMICO | S1: TIPO DE EXAMEN | T1: STATUS DE EXAMEN | U1: ENTREGA DE DOCUMENTOS | V1: OBSERVACION | W1: ASESORA
A2: 0 | B2: Percy flores quintana | C2: 51987654321 | D2: percy91.9fm@gmail.com | E2: terminé_el_colegio | G2: COMUNICACIONES | H2: PAUTA DIGITAL | K2: Open Day 3 | L2: Open Day 3 | M2: 45880 | N2: INCONTACTABLE | O2: INCONTACTABLE | P2: INCONTACTABLE | W2: Sheyla Peña
A3: 0 | B3: Jorge Luis | C3: 924212271 | D3: valuis854@gmail.com | E3: terminé_el_colegio | G3: TURISMO | H3: PAUTA DIGITAL | I3: SURQUILLO | K3: Visita Guiada | M3: 45846 | N3: SE ENVIÓ INFORMACIÓN | O3: NO CONTESTA | P3: NO CONTESTA | V3: jueves_11_a.m. | W3: Pya Pinto
A4: 0 | B4: Gian Taco melo | C4: 916287392 | D4: #¿NOMBRE? | G4: PSICOLOGIA | H4: CENTRAL | M4: 45859 | N4: SE ENVIÓ INFORMACIÓN | W4: Melisa Arciga
A5: 0 | B5: Jorge Luis orellano Fernández | C5: 51911111111 | D5: jtacuri@gmail.com | E5: terminé_el_colegio | G5: PSICOLOGIA | H5: PAUTA DIGITAL | K5: Examen Digital | L5: Examen Digital | M5: 45873 | N5: INCONTACTABLE | O5: INCONTACTABLE | P5: INCONTACTABLE | W5: Melisa Arciga
A6: 0 | B6: Elita Valverde | C6: 51991831956 | D6: clauvalverdebravo@gmail.com | E6: terminé_el_colegio | G6: TURISMO | H6: PAUTA DIGITAL | K6: Admisión regular | L6: Admisión regular | M6: 45880 | N6: SE ENVIÓ INFORMACIÓN | W6: Melisa Arciga
A7: 0 | B7: Florpumacayomartinez@gmail.com | C7: 51974540792 | D7: florpumacayomartinez@gmail.com | E7: terminé_el_colegio | G7: COMUNICACIONES | H7: PAUTA DIGITAL | K7: Taller Vivencial 3 | M7: 45856 | N7: SE ENVIÓ INFORMACIÓN | P7: NO CONTESTA | W7: Lilya Espinoza
A8: 0.8195499 | B8: Daniel Cornejo Marsano | C8: 935177607 | G8: COMUNICACIONES | H8: COUNTER | J8: 2026-I | L8: Taller Vivencial 3 | N8: MOSTRÓ INTERÉS | W8: Sheyla Peña
A9: 14 | B9: DAYANA ANGELICA | C9: 920459419 | G9: PSICOLOGIA | H9: CENTRAL | J9: 2025-II | N9: SE ENVIÓ INFORMACIÓN | O9: NO CONTESTA | W9: Melisa Arciga
A10: 35 | B10: ALVARO MORAN RODRIGUEZ | C10: 928768676 | G10: PSICOLOGIA | H10: CENTRAL | J10: 2025-II | N10: SE ENVIÓ INFORMACIÓN | O10: MOSTRÓ INTERÉS | W10: Melisa Arciga
A11: 78 | B11: IRMA LLAMOCCA | C11: 926617690 | G11: PSICOLOGIA | H11: CENTRAL | J11: 2025-II | N11: SE ENVIÓ INFORMACIÓN | O11: NO CONTESTA | W11: Melisa Arciga
A12: 578 | B12: KRISSTEL OTINIANO PALACIOS | C12: 922583646 | G12: COMUNICACIONES | H12: CENTRAL | I12: SURQUILLO | J12: 2025-II | N12: SE ENVIÓ INFORMACIÓN | W12: Melisa Arciga
A13: 85728 | B13: Isis Manrique | C13: 924459370 | D13: danaisis@hotmail.com | G13: PSICOLOGIA | H13: CENTRAL | I13: LIMA | L13: Taller Vivencial 3 | M13: 45854 | N13: SE ENVIO INFORMACION | O13: NO CONTESTA | W13: Pya Pinto
A14: 95016 | B14: KARLA NICOLE ACEVEDO ESPINOZA | C14: 936432292 | D14: KARLACEVEDO2009@GMAIL.COM | G14: PSICOLOGIA | H14: CENTRAL | J14: 2025-II | M14: 45841 | N14: SE ENVIÓ INFORMACIÓN | O14: NO CONTESTA | W14: Estrella Vergara
A15: 112233 | B15: Milagros Sandro Del Pozo | C15: 952686711 | D15: d00498116x@perueduca.edu.pe | E15: 5TO | F15: ORDINARIO | G15: PSICOLOGIA | H15: PAUTA DIGITAL | I15: SURQUILLO | L15: Taller Vivencial 3 | M15: 45845 | N15: SE ENVIÓ INFORMACIÓN | O15: EVALUANDO OPCIONES | P15: EVALUANDO OPCIONES | W15: Pya Pinto
A16: 125877 | B16: Carmel Art | C16: 51947468123 | D16: Carmencita_art@hotmail.com | E16: TERMINÉ EL COLEGIO | F16: ORDINARIO | G16: PSICOLOGIA | H16: PAUTA DIGITAL | J16: 2025-II | L16: Taller Vivencial 3 | N16: SE ENVIÓ INFORMACIÓN | W16: Sheyla Peña
A17: 283550 | B17: Natacha Hernandez Caruto | C17: 51908875718 | D17: caruto_18@hotmail.com | G17: PSICOLOGIA | H17: CENTRAL | J17: 2025-II | M17: 45841 | N17: SE ENVIÓ INFORMACIÓN | V17: CENTRAL | W17: Lilya Espinoza
A18: 428783 | B18: Jesús Paúcar Moreano | C18: 934063636 | D18: jpaucar2@gmail.com | E18: terminé_el_colegio | G18: COMUNICACIONES | H18: PAUTA DIGITAL | K18: Open Day 3 | L18: Open Day 3 | M18: 45876 | N18: SE ENVIÓ INFORMACIÓN | W18: Estrella Vergara
A19: 507578 | B19: Mery Sosa Camma | C19: 51 992 352 828 | D19: merysosa06@gmail.com | G19: TURISMO | H19: EVENTO PRESENCIAL | I19: SURQUILLO | J19: 2025-II | N19: NO CONTESTA | O19: NO CONTESTA | P19: NO CONTESTA | W19: Lilya Espinoza
A20: 513208 | B20: David Maquera | C20: 51999225125 | D20: dmaquera2004@gmail.com | G20: PSICOLOGIA | H20: CENTRAL | J20: 2025-II | M20: 45841 | N20: SE ENVIÓ INFORMACIÓN | V20: CENTRAL | W20: Pya Pinto
A21: 606162 | B21: hermelinda segobia huarancca | C21: 937382639 | G21: TURISMO | H21: CENTRAL | L21: Open Day 3 | M21: 45880 | N21: MOSTRO INTERES | O21: SI CONFIRMÓ PARA EL EVENTO | P21: SI CONFIRMÓ PARA EL EVENTO | W21: Pya Pinto
A22: 613148 | B22: COLMENARES LUGO GABRIEL | C22: 51920305634 | D22: gabrielcolmenares774@gmail.com | G22: PSICOLOGIA | H22: PAUTA DIGITAL | J22: 2025-II | K22: Open Day 2 | L22: Open Day 2 | N22: SE ENVIÓ INFORMACIÓN | W22: Lilya Espinoza
A23: 618432 | B23: Diego Penito | C23: 942139910 | D23: Diego.penito@gmail.com | G23: TURISMO | H23: PAUTA DIGITAL | I23: SURQUILLO | J23: 2025-II | N23: SE ENVIÓ INFORMACIÓN | O23: NO CONTESTA | P23: NO CONTESTA | W23: Melisa Arciga
A24: 714637 | B24: Gabriela | C24: 938219941 | D24: fiestaslamiley@gmail.com | G24: PSICOLOGIA | H24: PAUTA DIGITAL | I24: SURQUILLO | J24: 2025-II | N24: SE ENVIÓ INFORMACIÓN | O24: NO CONTESTA | W24: Melisa Arciga
A25: 722570 | B25: Oriana | C25: 51938937145 | D25: oriana.reve@gmail.com | G25: COMUNICACIONES | H25: PAUTA DIGITAL | I25: SURQUILLO | J25: 2025-II | K25: Taller Vivencial 3 | L25: Taller Vivencial 3 | N25: MOSTRÓ INTERÉS | O25: SI CONFIRMÓ PARA EL EVENTO | W25: Pya Pinto
A26: 806080 | B26: Greisy Primera | C26: 948064920 | D26: primerageily@gmail.com | G26: PSICOLOGIA | H26: CENTRAL | J26: 2025-II | N26: SE ENVIÓ INFORMACIÓN | O26: MOSTRÓ INTERÉS | W26: Melisa Arciga
A27: 857281 | B27: Isis Manrique | C27: 51924459370 | D27: danaisis@hotmail.com | E27: terminé_el_colegio | F27: ORDINARIO | G27: PSICOLOGIA | H27: PAUTA DIGITAL | K27: Admisión regular | L27: Admisión regular | M27: 45849 | N27: SE ENVIÓ INFORMACIÓN | W27: Estrella Vergara
A28: 912327 | B28: Diego Vega | C28: 915269388 | D28: dvegacn@gmail.com | G28: COMUNICACIONES | H28: PAUTA DIGITAL | J28: 2025-II | K28: Taller Vivencial 2 | L28: Taller Vivencial 3 | N28: SE ENVIÓ INFORMACIÓN | O28: NO CONTESTA | W28: Sheyla Peña
A29: 919237 | B29: the_diamond_dv | C29: 51915111599 | D29: ferjesus88@hotmail.com | G29: COMUNICACIONES | H29: PAUTA DIGITAL | I29: SURQUILLO | J29: 2025-II | K29: Open Day 2 | L29: Open Day 2 | N29: NO CONTESTA | O29: NO CONTESTA | P29: NO CONTESTA | W29: Pya Pinto
A30: 1114661 | B30: Marco Andres | C30: 902632791 | D30: marcoamaya2008@gmail.com | G30: TURISMO | H30: CENTRAL | J30: 2025-II | M30: 45841 | N30: SE ENVIÓ INFORMACIÓN | V30: CENTRAL | W30: Pya Pinto
A31: 1345107 | B31: Liz Regina Maraza | C31: 973133850 | D31: rhondagroupholding@gmail.com | E31: terminé_el_colegio | F31: ORDINARIO | G31: PSICOLOGIA | H31: PAUTA DIGITAL | I31: SURQUILLO | J31: 2025-II | N31: SE ENVIÓ INFORMACIÓN | O31: MOSTRÓ INTERÉS | W31: Melisa Arciga
A32: 1367992 | B32: EMILIA PONCELEON MARTINEZ | C32: 982752611 | D32: emiliaponceleon@gmail.com | G32: COMUNICACIONES | H32: CENTRAL | J32: 2025-II | M32: 45841 | N32: SE ENVIÓ INFORMACIÓN | V32: CENTRAL | W32: Lilya Espinoza
A33: 1438773 | B33: Francia Elena Cruz Herrera | C33: 51965825500 | D33: franciaherrera1626@hotmail.com | G33: PSICOLOGIA | H33: PAUTA DIGITAL | J33: 2025-II | K33: Open Day 2 | L33: Open Day 2 | N33: SE ENVIÓ INFORMACIÓN | W33: Lilya Espinoza
A34: 1457920 | B34: Camila Victoria Campos | C34: 930769860 | D34: gatitolover27@gmail.com | G34: PSICOLOGIA | H34: CENTRAL | J34: 2025-II | M34: 45841 | N34: SE ENVIÓ INFORMACIÓN | V34: CENTRAL | W34: Pya Pinto
A35: 1461367 | B35: Roxana urbina | C35: 936019829 | D35: roxanaurbina_10297@hotmail.com | G35: PSICOLOGIA | H35: WEB | J35: 2025-II | M35: 45841 | N35: OTROS | V35: DIO EXAMEN EN CENTRAL | W35: Lilya Espinoza
A36: 1545103 | B36: Renata Franco | C36: 939281557 | D36: renatafranco86@gmail.com | E36: TERMINÉ EL COLEGIO | F36: ORDINARIO | G36: PSICOLOGIA | H36: PAUTA DIGITAL | I36: SURQUILLO | J36: 2025-II | N36: NO CONTESTA | W36: Estrella Vergara
A37: 1670664 | B37: Marco Paredes | C37: 51903433502 | D37: marcoantoniopa.so171@gmail.com | G37: TURISMO | H37: CENTRAL | J37: 2025-II | M37: 45841 | N37: SE ENVIÓ INFORMACIÓN | V37: CENTRAL | W37: Lilya Espinoza
A38: 1862131 | B38: Richard Lenin | C38: 933655616 | D38: richardlenin@gmail.com | E38: terminé_el_colegio | G38: COMUNICACIONES | H38: CENTRAL | K38: Examen Digital | L38: Examen Digital | M38: 45880 | N38: SE ENVIO INFORMACION | W38: Pya Pinto
A39: 1862131 | B39: Richard Lenin | C39: 933655616 | D39: richardlenin@gmail.com | G39: COMUNICACIONES | H39: CENTRAL | L39: Open Day 3 | M39: 45880 | N39: SE ENVIO INFORMACION | W39: Pya Pinto
A40: 1942861 | B40: ANTONIO PAEZ TOMASSI | C40: 931125510 | G40: PSICOLOGIA | H40: CENTRAL | J40: 2025-II | M40: 45841 | N40: INCONTACTABLE | O40: NO CONTESTA | V40: CENTRAL | W40: Sheyla Peña
...

Sheet BD|Pya P.
A1: DNI | B1: NOMBRES | C1: CELULAR | D1: CORREO | E1: COLEGIO DE PROCEDENCIA | F1: MODALIDAD | G1: ESCUELA | H1: ORIGEN | I1: SEDE | J1: SEMESTRE | K1: CAMPAÑA | L1: EVENTO | M1: FECHA DE INGRESO DE LEAD | N1: CONTACTO I | O1: CONTACTO II | P1: CONTACTO III | Q1: ¿PAGÓ DERECHO DE INSCRIPCIÓN? | R1: STATUS ACADÉMICO | S1: TIPO DE EXAMEN | T1: STATUS DE EXAMEN | U1: ENTREGA DE DOCUMENTOS | V1: OBSERVACION
A2: 75692011 | B2: Leonardo Joaquín Torres Soria | C2: 987844691 | D2: leonardojoaquin_ts@hotmail.com | E2: TERMINO EL COLEGIO | F2: ORDINARIO | G2: COMUNICACIONES | H2: PAUTA DIGITAL | I2: SURQUILLO | J2: 2025-II | K2: Taller Vivencial 2 | L2: Taller Vivencial 2 | N2: MOSTRÓ INTERÉS | O2: MOSTRÓ INTERÉS | P2: =TRIM(BD_PyaPinto[[#This Row],[CONTACTO II]]) -> MOSTRÓ INTERÉS | Q2: NO - VIRTUAL | R2: ADMITIDO | S2: VIRTUAL | T2: RINDIO VIRTUAL | U2: PENDIENTE TODO
A3: 74683685 | B3: Ruiz Grippa Fabian Emilio | C3: 930 802 194 | D3: fabianemilioruizgrippa@gmail.com | F3: ORDINARIO | G3: COMUNICACIONES | H3: BASE ANTIGUA | I3: SURQUILLO | J3: 2025-II | N3: MOSTRÓ INTERÉS | O3: MOSTRÓ INTERÉS | P3: =TRIM(BD_PyaPinto[[#This Row],[CONTACTO II]]) -> MOSTRÓ INTERÉS | Q3: NO - VIRTUAL | R3: ADMITIDO | S3: VIRTUAL | T3: RINDIO VIRTUAL | U3: PENDIENTE TODO
A4: 41810776 | B4: Omar Arturo Contreras Costilla | C4: 951199456 | D4: oacontrerascostilla@gmail.com | G4: COMUNICACIONES | H4: PAUTA DIGITAL | I4: SURQUILLO | J4: 2025-II | K4: Taller Vivencial 2 | L4: Open Day 3 | N4: SE ENVIÓ INFORMACIÓN | O4: ESPERANDO CONFIRMACIÓN PARA EL EVENTO | P4: ESPERANDO CONFIRMACIÓN PARA EL EVENTO
A5: 6752323 | B5: Vicente Ore Arango | C5: 986529513 | D5: orearangovicente@gmail.com | G5: COMUNICACIONES | H5: PAUTA DIGITAL | I5: SURQUILLO | J5: 2025-II | K5: Taller Vivencial 3 | L5: Taller Vivencial 3 | N5: MOSTRÓ INTERÉS | O5: SI CONFIRMÓ PARA EL EVENTO
A6: 40946106 | B6: Evelyn Leon | C6: 51992288193 | D6: eleonr2603@gmail.com | G6: COMUNICACIONES | H6: PAUTA DIGITAL | I6: SURQUILLO | J6: 2025-II | K6: Taller Vivencial 2 | L6: Taller Vivencial 2 | N6: SE ENVIÓ INFORMACIÓN | O6: MOSTRÓ INTERÉS | P6: =TRIM(BD_PyaPinto[[#This Row],[CONTACTO II]]) -> MOSTRÓ INTERÉS
A7: 71407994 | B7: Martín David Aguirre De La Cruz | C7: 931001314 | G7: TURISMO | H7: PAUTA DIGITAL | I7: SURQUILLO | J7: 2025-II | N7: MOSTRÓ INTERÉS | O7: MOSTRÓ INTERÉS | P7: =TRIM(BD_PyaPinto[[#This Row],[CONTACTO II]]) -> MOSTRÓ INTERÉS
A8: 71365616 | B8: Ariana Thais Sánchez Rupay | C8: 51992025484 | D8: arianitalinda17@gmail.com | G8: COMUNICACIONES | H8: PAUTA DIGITAL | I8: SURQUILLO | J8: 2025-II | K8: Open Day 2 | L8: Open Day 2 | N8: MOSTRÓ INTERÉS | O8: MOSTRÓ INTERÉS | P8: =TRIM(BD_PyaPinto[[#This Row],[CONTACTO II]]) -> MOSTRÓ INTERÉS
A9: 61516770 | B9: Thays Salazar | C9: 51965108345 | D9: thayssalazarvilchez@gmail.com | G9: COMUNICACIONES | H9: PAUTA DIGITAL | I9: SURQUILLO | J9: 2025-II | K9: Open Day 2 | L9: Open Day 2 | N9: NO CONTESTA | O9: MOSTRÓ INTERÉS | P9: =TRIM(BD_PyaPinto[[#This Row],[CONTACTO II]]) -> MOSTRÓ INTERÉS
A10: 42258994 | B10: LUCIA MERCEDES ROCHA MONTES | C10: 922863982 | D10: lucia.rochamontes@gmail.com | G10: COMUNICACIONES | H10: PAUTA DIGITAL | I10: SURQUILLO | J10: 2025-II | K10: Taller Vivencial 3 | L10: Open Day 3 | N10: SE ENVIÓ INFORMACIÓN | O10: ESPERANDO CONFIRMACIÓN PARA EL EVENTO | P10: ESPERANDO CONFIRMACIÓN PARA EL EVENTO
A11: 61022476 | B11: Joaquin Aleph Arribasplata Castañeda | C11: 997351278 | D11: jarribasplata88@gmail.com | E11: TERMINÉ EL COLEGIO | G11: COMUNICACIONES | H11: COUNTER | I11: SURQUILLO | J11: 2025-II | N11: MOSTRÓ INTERÉS | O11: MOSTRÓ INTERÉS | P11: =TRIM(BD_PyaPinto[[#This Row],[CONTACTO II]]) -> MOSTRÓ INTERÉS | Q11: NO - VIRTUAL | R11: ADMITIDO | S11: VIRTUAL | T11: RINDIO VIRTUAL | U11: PENDIENTE TODO
A12: 60492449 | B12: Ainnara Alvarado Paucar | C12: 941275338 | D12: Kimberlyalvarado0504@gmail.com | E12: TERMINÉ EL COLEGIO | G12: COMUNICACIONES | H12: PAUTA DIGITAL | I12: SURQUILLO | J12: 2025-II | K12: Open Day 2 | L12: Open Day 2 | N12: MOSTRÓ INTERÉS | O12: MOSTRÓ INTERÉS | P12: =TRIM(BD_PyaPinto[[#This Row],[CONTACTO II]]) -> MOSTRÓ INTERÉS
A13: 722570 | B13: Oriana | C13: 51938937145 | D13: oriana.reve@gmail.com | G13: COMUNICACIONES | H13: PAUTA DIGITAL | I13: SURQUILLO | J13: 2025-II | K13: Taller Vivencial 3 | L13: Taller Vivencial 3 | N13: MOSTRÓ INTERÉS | O13: SI CONFIRMÓ PARA EL EVENTO
B14: Juana Costilla Cahuaza | C14: 912031310 | D14: thaismencardenas@gmail.com | G14: COMUNICACIONES | H14: PAUTA DIGITAL | I14: SURQUILLO | J14: 2025-II | K14: Open Day 1 | L14: Open Day 1 | N14: MOSTRÓ INTERÉS | O14: MOSTRÓ INTERÉS | P14: =TRIM(BD_PyaPinto[[#This Row],[CONTACTO II]]) -> MOSTRÓ INTERÉS
B15: Jade Paredes Vargas | C15: 987193401 | D15: irennechafio@gmail.com | G15: COMUNICACIONES | H15: PAUTA DIGITAL | I15: SURQUILLO | J15: 2025-II | K15: Open Day 1 | L15: Open Day 1 | N15: MOSTRÓ INTERÉS | O15: MOSTRÓ INTERÉS | P15: =TRIM(BD_PyaPinto[[#This Row],[CONTACTO II]]) -> MOSTRÓ INTERÉS
B16: Ally | C16: 923025308 | D16: alexander200208ga@gmail.com | G16: COMUNICACIONES | H16: PAUTA DIGITAL | I16: SURQUILLO | J16: 2025-II | K16: Open Day 1 | L16: Open Day 1 | N16: SE ENVIÓ INFORMACIÓN | O16: NO CONTESTA | P16: =TRIM(BD_PyaPinto[[#This Row],[CONTACTO II]]) -> NO CONTESTA
B17: Lilian Rosario Oviedo Diaz | C17: 954561892 | D17: gimena9@outlook.com | G17: COMUNICACIONES | H17: PAUTA DIGITAL | I17: SURQUILLO | J17: 2025-II | K17: Open Day 1 | L17: Open Day 1 | N17: MOSTRÓ INTERÉS | O17: MOSTRÓ INTERÉS | P17: =TRIM(BD_PyaPinto[[#This Row],[CONTACTO II]]) -> MOSTRÓ INTERÉS
B18: Rosa Marin Alcantara | C18: 924148943 | D18: jennifer2007laroso@gmail.com | G18: COMUNICACIONES | H18: PAUTA DIGITAL | I18: SURQUILLO | J18: 2025-II | K18: Open Day 1 | L18: Open Day 1 | N18: NO CONTESTA | O18: NO CONTESTA | P18: =TRIM(BD_PyaPinto[[#This Row],[CONTACTO II]]) -> NO CONTESTA
B19: Juovisa | C19: 954043244 | D19: mrojasrossell.sap@gmail.com | G19: COMUNICACIONES | H19: PAUTA DIGITAL | I19: SURQUILLO | J19: 2025-II | K19: Open Day 1 | L19: Open Day 1 | N19: SE ENVIÓ INFORMACIÓN | O19: NO CONTESTA | P19: =TRIM(BD_PyaPinto[[#This Row],[CONTACTO II]]) -> NO CONTESTA
B20: Araziel Vallejo | C20: 936236347 | D20: arazielvallejo@gmail.com | G20: COMUNICACIONES | H20: PAUTA DIGITAL | I20: SURQUILLO | J20: 2025-II | K20: Open Day 1 | L20: Open Day 1 | N20: MOSTRÓ INTERÉS | O20: MOSTRÓ INTERÉS | P20: =TRIM(BD_PyaPinto[[#This Row],[CONTACTO II]]) -> MOSTRÓ INTERÉS
A21: 71182199 | B21: Avril Fernanda Trigoso Guillén | C21: 961611547 | D21: belyguillen@hotmail.com | G21: COMUNICACIONES | H21: PAUTA DIGITAL | I21: SURQUILLO | J21: 2025-II | K21: Taller Vivencial 3 | L21: Open Day 3 | N21: MOSTRÓ INTERÉS | O21: SI CONFIRMÓ PARA EL EVENTO | P21: SI CONFIRMÓ PARA EL EVENTO
A22: 43247154 | B22: flaviana Luciana Huanca Bravo | C22: 999497134 | D22: katrina2825@gmail.com | G22: COMUNICACIONES | H22: PAUTA DIGITAL | I22: SURQUILLO | J22: 2025-II | K22: Taller Vivencial 2 | L22: Taller Vivencial 2 | N22: MOSTRÓ INTERÉS | O22: MOSTRÓ INTERÉS | P22: MOSTRÓ INTERÉS
A23: 71175910 | B23: Valentino Imanol Campos Cueva | C23: 939 623 999 | D23: jessicacuevagz@gmail.com | F23: ORDINARIO | G23: PSICOLOGIA | H23: BASE ANTIGUA | I23: SURQUILLO | J23: 2025-II | N23: MOSTRÓ INTERÉS | O23: MOSTRÓ INTERÉS | P23: =TRIM(BD_PyaPinto[[#This Row],[CONTACTO II]]) -> MOSTRÓ INTERÉS | Q23: NO - VIRTUAL | R23: ADMITIDO | S23: VIRTUAL | T23: RINDIO VIRTUAL | U23: ENTREGADO-COMPLETO
A24: 70629594 | B24: Luis Fernando Martinez Ventura | C24: 926603128 | D24: martinezventuraluis1@gmail.com | E24: William Shakespeare | F24: ORDINARIO | G24: PSICOLOGIA | H24: EVENTO PRESENCIAL | I24: SURQUILLO | J24: 2025-II | L24: Taller Vivencial 3 | N24: MOSTRÓ INTERÉS | O24: MOSTRÓ INTERÉS | Q24: NO - VIRTUAL | R24: ADMITIDO | S24: VIRTUAL | T24: RINDIO VIRTUAL | U24: PENDIENTE TODO
B25: Samantha Alva | C25: 937799459 | D25: tatiana.salazar.canepa@gmail.com | G25: PSICOLOGIA | H25: PAUTA DIGITAL | I25: SURQUILLO | J25: 2025-II | K25: Open Day 1 | L25: Open Day 1 | N25: SE ENVIÓ INFORMACIÓN | O25: SE ENVIÓ INFORMACIÓN | P25: =TRIM(BD_PyaPinto[[#This Row],[CONTACTO II]]) -> SE ENVIÓ INFORMACIÓN
B26: Anjely | C26: 993229334 | D26: alberto_1177@hotmail.com | G26: PSICOLOGIA | H26: PAUTA DIGITAL | I26: SURQUILLO | J26: 2025-II | K26: Open Day 1 | L26: Open Day 1 | N26: MOSTRÓ INTERÉS | O26: MOSTRÓ INTERÉS | P26: =TRIM(BD_PyaPinto[[#This Row],[CONTACTO II]]) -> MOSTRÓ INTERÉS
B27: Akemi Inft | C27: 942972438 | D27: Rox1612.sorsan@gmal.com | G27: PSICOLOGIA | H27: PAUTA DIGITAL | I27: SURQUILLO | J27: 2025-II | K27: Open Day 1 | L27: Open Day 1 | N27: SE ENVIÓ INFORMACIÓN | O27: SE ENVIÓ INFORMACIÓN | P27: =TRIM(BD_PyaPinto[[#This Row],[CONTACTO II]]) -> SE ENVIÓ INFORMACIÓN
B28: Cristina Saavedra Huaman | C28: 971582144 | D28: vilchezpame29@gmail.com | G28: PSICOLOGIA | H28: PAUTA DIGITAL | I28: SURQUILLO | J28: 2025-II | K28: Open Day 1 | L28: Open Day 3 | N28: MOSTRÓ INTERÉS | O28: SI CONFIRMÓ PARA EL EVENTO | P28: SI CONFIRMÓ PARA EL EVENTO
B29: Dana | C29: 951133785 | D29: angescalpe@gmail.com | G29: PSICOLOGIA | H29: PAUTA DIGITAL | I29: SURQUILLO | J29: 2025-II | K29: Open Day 1 | L29: Open Day 1 | N29: NO CONTESTA | O29: NO CONTESTA | P29: =TRIM(BD_PyaPinto[[#This Row],[CONTACTO II]]) -> NO CONTESTA
B30: Anni Dariana Lazo Caceres | C30: 929159506 | D30: villanuevacastrodulce@gmail.com | G30: PSICOLOGIA | H30: PAUTA DIGITAL | I30: SURQUILLO | J30: 2025-II | K30: Open Day 1 | L30: Open Day 1 | N30: MOSTRÓ INTERÉS | O30: MOSTRÓ INTERÉS | P30: =TRIM(BD_PyaPinto[[#This Row],[CONTACTO II]]) -> MOSTRÓ INTERÉS
B31: Luis Andre Ruiz Icochea | C31: 984838423 | D31: rosa.marin.alcantara@hotmail.com | G31: PSICOLOGIA | H31: PAUTA DIGITAL | I31: SURQUILLO | J31: 2025-II | K31: Open Day 1 | L31: Open Day 1 | N31: SE ENVIÓ INFORMACIÓN | O31: SE ENVIÓ INFORMACIÓN | P31: =TRIM(BD_PyaPinto[[#This Row],[CONTACTO II]]) -> SE ENVIÓ INFORMACIÓN
B32: Yolanda Salinas Ramirez | C32: 987863691 | D32: emilycordovam15@gmail.com | G32: PSICOLOGIA | H32: PAUTA DIGITAL | I32: SURQUILLO | J32: 2025-II | K32: Open Day 1 | L32: Open Day 1 | N32: NO CONTESTA | O32: NO CONTESTA | P32: =TRIM(BD_PyaPinto[[#This Row],[CONTACTO II]]) -> NO CONTESTA
B33: Dash Rivera | C33: 945236476 | D33: sandrawongpe@gmail.com | G33: PSICOLOGIA | H33: PAUTA DIGITAL | I33: SURQUILLO | J33: 2025-II | K33: Open Day 1 | L33: Open Day 1 | N33: SE ENVIÓ INFORMACIÓN | O33: NO CONTESTA | P33: =TRIM(BD_PyaPinto[[#This Row],[CONTACTO II]]) -> NO CONTESTA
B34: Ashley | C34: 967574438 | D34: lruizicochea@gmail.com | G34: PSICOLOGIA | H34: PAUTA DIGITAL | I34: SURQUILLO | J34: 2025-II | K34: Open Day 1 | L34: Open Day 1 | N34: SE ENVIÓ INFORMACIÓN | O34: SE ENVIÓ INFORMACIÓN | P34: =TRIM(BD_PyaPinto[[#This Row],[CONTACTO II]]) -> SE ENVIÓ INFORMACIÓN
B35: Katherine Nicole Gomez Gago | C35: 982007153 | D35: msalinasramirez@hotmail.com | G35: PSICOLOGIA | H35: PAUTA DIGITAL | I35: SURQUILLO | J35: 2025-II | K35: Open Day 1 | L35: Open Day 1 | N35: MOSTRÓ INTERÉS | O35: MOSTRÓ INTERÉS | P35: =TRIM(BD_PyaPinto[[#This Row],[CONTACTO II]]) -> MOSTRÓ INTERÉS
B36: Ariana Aylas Tenorio | C36: 956251170 | D36: connietr31@gmail.com | G36: PSICOLOGIA | H36: PAUTA DIGITAL | I36: SURQUILLO | J36: 2025-II | K36: Open Day 1 | L36: Open Day 1 | N36: MOSTRÓ INTERÉS | O36: MOSTRÓ INTERÉS | P36: =TRIM(BD_PyaPinto[[#This Row],[CONTACTO II]]) -> MOSTRÓ INTERÉS
B37: Brunella | C37: 941064232 | D37: brune.scc@gmail.com | G37: PSICOLOGIA | H37: PAUTA DIGITAL | I37: SURQUILLO | J37: 2025-II | K37: Open Day 1 | L37: Open Day 1 | N37: SE ENVIÓ INFORMACIÓN | O37: NO CONTESTA | P37: =TRIM(BD_PyaPinto[[#This Row],[CONTACTO II]]) -> NO CONTESTA
A38: 42512860 | B38: Luciana Brissa Camiloaga Villanueva | C38: 933671229 | G38: PSICOLOGIA | H38: EVENTO PRESENCIAL | I38: SURQUILLO | J38: 2025-II | N38: MOSTRÓ INTERÉS | O38: MOSTRÓ INTERÉS | P38: =TRIM(BD_PyaPinto[[#This Row],[CONTACTO II]]) -> MOSTRÓ INTERÉS | Q38: NO - VIRTUAL | R38: ADMITIDO | S38: VIRTUAL | T38: RINDIO VIRTUAL | U38: PENDIENTE TODO
A39: 60919373 | B39: Fatima | C39: 993577915 | D39: ayelenur24@gmail.com | G39: COMUNICACIONES | H39: PAUTA DIGITAL | I39: SURQUILLO | J39: 2025-II | K39: Open Day 2 | L39: Open Day 2 | N39: SE ENVIÓ INFORMACIÓN | O39: NO CONTESTA | P39: =TRIM(BD_PyaPinto[[#This Row],[CONTACTO II]]) -> NO CONTESTA
A40: 7749489 | B40: Mayco Méndez Alva | C40: 51993324451 | D40: mmendezalva@gmail.com | G40: PSICOLOGIA | H40: PAUTA DIGITAL | I40: SURQUILLO | J40: 2025-II | K40: Taller Vivencial 2 | L40: Taller Vivencial 2 | N40: SE ENVIÓ INFORMACIÓN | O40: NO CONTESTA | P40: =TRIM(BD_PyaPinto[[#This Row],[CONTACTO II]]) -> NO CONTESTA
...

Sheet BD|Melisa A.
A1: DNI | B1: NOMBRES | C1: CELULAR | D1: CORREO | E1: COLEGIO DE PROCEDENCIA | F1: MODALIDAD | G1: ESCUELA | H1: ORIGEN | I1: SEDE | J1: SEMESTRE | K1: CAMPAÑA | L1: EVENTO | M1: FECHA DE INGRESO DE LEAD | N1: CONTACTO I | O1: CONTACTO II | P1: CONTACTO III | Q1: ¿PAGÓ DERECHO DE INSCRIPCIÓN? | R1: STATUS ACADÉMICO | S1: TIPO DE EXAMEN | T1: STATUS DE EXAMEN | U1: ENTREGA DE DOCUMENTOS | V1: OBSERVACION
B2: Azumy Aleshka Melany Ramos Castro | C2: 966479008 | D2: sandyrodo@gmail.com | G2: COMUNICACIONES | H2: PAUTA DIGITAL | I2: SURQUILLO | J2: 2025-II | N2: SE ENVIÓ INFORMACIÓN | O2: NO CONTESTA | P2: MOSTRÓ INTERÉS | S2: VIRTUAL | T2: RINDIO VIRTUAL | U2: ENTREGADO-COMPLETO
A3: 60973530 | B3: MACCIEL SOIREMA CHAVEZ ESTIBUR | C3: 963 333 412 | D3: macciellestibur28@gmail.com | F3: ORDINARIO | G3: COMUNICACIONES | H3: BASE ANTIGUA | I3: SURQUILLO | J3: 2025-II | K3: Open Day 3 | L3: Open Day 3 | N3: SE ENVIÓ INFORMACIÓN | O3: SI CONFIRMÓ PARA EL EVENTO | P3: SI CONFIRMÓ PARA EL EVENTO | Q3: NO- VIRTUAL | R3: ADMITIDO | S3: VIRTUAL | T3: RINDIO VIRTUAL | U3: ENTREGADO-COMPLETO
A4: 72595939 | B4: Nicolás Adriano Carrillo Castillo | C4: 956693526 | D4: kari19_05@hotmail.com | G4: COMUNICACIONES | H4: PAUTA DIGITAL | I4: SURQUILLO | J4: 2025-II | N4: SE ENVIÓ INFORMACIÓN | O4: MOSTRÓ INTERÉS | P4: MOSTRÓ INTERÉS
A5: 10119327 | B5: Giovanna MedaliYazu | C5: 51980769656 | D5: giovannahuamanchay@gmail.com | G5: COMUNICACIONES | H5: PAUTA DIGITAL | I5: SURQUILLO | J5: 2025-II | N5: SE ENVIÓ INFORMACIÓN | O5: NO CONTESTA | P5: NO CONTESTA
A6: 9877154 | B6: Janeth Huapaya | C6: 51999343475 | D6: Janyht_74@hotmail.com | G6: COMUNICACIONES | H6: PAUTA DIGITAL | I6: SURQUILLO | J6: 2025-II | N6: SE ENVIÓ INFORMACIÓN | O6: NO CONTESTA | P6: NO CONTESTA
A7: 60797702 | B7: Daniel Alcides Quispe Ataqui | C7: 992 513 409 | D7: Cremitadaniel@gmail.com | F7: ORDINARIO | G7: COMUNICACIONES | H7: BASE ANTIGUA | I7: SURQUILLO | J7: 2025-II | N7: MOSTRÓ INTERÉS | O7: MOSTRÓ INTERÉS | P7: MOSTRÓ INTERÉS | Q7: NO- VIRTUAL | R7: ADMITIDO | S7: VIRTUAL | T7: RINDIO VIRTUAL | U7: ENTREGADO-COMPLETO
A8: 42389216 | B8: niebve | C8: 51970735881 | D8: adriantomasto20@gmail.com | G8: COMUNICACIONES | H8: PAUTA DIGITAL | I8: SURQUILLO | J8: 2025-II | N8: SE ENVIÓ INFORMACIÓN | O8: MOSTRÓ INTERÉS | P8: MOSTRÓ INTERÉS
A9: 73280352 | B9: Andy Subilete ramos | C9: +51 939 944 297 | D9: tanianicolsubilete@gmail.com | G9: COMUNICACIONES | H9: PAUTA DIGITAL | I9: SURQUILLO | J9: 2025-II | N9: SE ENVIÓ INFORMACIÓN | O9: MOSTRÓ INTERÉS | P9: MOSTRÓ INTERÉS
A10: 45373198 | B10: Jose Daniel Vergara | C10: 51983604664 | D10: danver.talent.88@gmail.com | G10: COMUNICACIONES | H10: PAUTA DIGITAL | I10: SURQUILLO | J10: 2025-II | N10: SE ENVIÓ INFORMACIÓN | O10: MOSTRÓ INTERÉS | P10: NO CONTESTA
A11: 61214259 | B11: Xiomara Minaya | C11: +51 914 811 977 | D11: minayaxiomara52@gmail.com | G11: COMUNICACIONES | H11: PAUTA DIGITAL | I11: SURQUILLO | J11: 2025-II | N11: SE ENVIÓ INFORMACIÓN | O11: MOSTRÓ INTERÉS | P11: NO CONTESTA
A12: 60810207 | B12: Rodrigo Aarón Pereira Soto | C12: 903160230 | G12: COMUNICACIONES | H12: COUNTER | I12: SURQUILLO | J12: 2025-II | N12: SE ENVIÓ INFORMACIÓN | O12: MOSTRÓ INTERÉS | P12: MOSTRÓ INTERÉS
A13: 61291439 | B13: LA BARRERA ROMERO MARK ANDREW | C13: +51 910 329 954 | G13: COMUNICACIONES | H13: COUNTER | I13: SURQUILLO | J13: 2025-II | N13: SE ENVIÓ INFORMACIÓN | O13: MOSTRÓ INTERÉS | P13: MOSTRÓ INTERÉS | Q13: NO- VIRTUAL | R13: ADMITIDO | S13: VIRTUAL | T13: RENDIRÁ VIRTUAL | U13: PENDIENTE TODO
A14: :61291439 | B14: Mark Andrew La Barrera Romero | C14: +51 910 329 954 | D14: marklabarreraromero@gmail.com | G14: COMUNICACIONES | H14: COUNTER | I14: SURQUILLO | J14: 2025-II | N14: SE ENVIÓ INFORMACIÓN | O14: MOSTRÓ INTERÉS | P14: MOSTRÓ INTERÉS | Q14: NO- VIRTUAL | R14: ADMITIDO | S14: VIRTUAL | T14: RENDIRÁ VIRTUAL | U14: PENDIENTE TODO
A15: 71174516 | B15: Andrea Leon Requelme | C15: +51 989 345 213 | G15: COMUNICACIONES | H15: COUNTER | I15: SURQUILLO | J15: 2025-II | N15: SE ENVIÓ INFORMACIÓN | O15: MOSTRÓ INTERÉS | P15: MOSTRÓ INTERÉS | Q15: NO- VIRTUAL | R15: ADMITIDO | S15: VIRTUAL | T15: RENDIRÁ VIRTUAL | U15: PENDIENTE TODO
A16: 61188538 | B16: Ariela Sumie Tokuno Sota | C16: +51 957 296 870 | D16: arielasumie@gmail.com | G16: COMUNICACIONES | H16: COUNTER | I16: SURQUILLO | J16: 2025-II | N16: SE ENVIÓ INFORMACIÓN | O16: MOSTRÓ INTERÉS | P16: MOSTRÓ INTERÉS | Q16: NO- VIRTUAL | R16: ADMITIDO | S16: VIRTUAL | T16: RINDIO VIRTUAL | U16: ENTREGADO-COMPLETO | V16: YA PAGO MATRICULA
A17: 61454758 | B17: 𝒜𝓃𝒶𝓂𝓎𝓁𝑒𝑒 | C17: 51929543197 | D17: anamiledaleshka@gmail.com | G17: COMUNICACIONES | H17: PAUTA DIGITAL | I17: SURQUILLO | J17: 2025-II | N17: SE ENVIÓ INFORMACIÓN | O17: NO CONTESTA | P17: NO CONTESTA
B18: Giuliano Salazar Torres | C18: 985645048 | D18: GIULIANOSALAZARTORRES@GMAIL.COM | G18: COMUNICACIONES | H18: PAUTA DIGITAL | I18: SURQUILLO | J18: 2025-II | N18: MOSTRÓ INTERÉS | O18: MOSTRÓ INTERÉS | P18: MOSTRÓ INTERÉS
B19: Yadhira Celestino | C19: 953800626 | D19: yadhiraxiomaracelestinogalvez@gmail.com | G19: COMUNICACIONES | H19: PAUTA DIGITAL | I19: SURQUILLO | J19: 2025-II | N19: NO CONTESTA | O19: NO CONTESTA | P19: INCONTACTABLE
B20: Andersson Rubén Quiquijana Salas | C20: 936479486 | D20: fcondori.es@gmail.com | G20: COMUNICACIONES | H20: PAUTA DIGITAL | I20: SURQUILLO | J20: 2025-II | N20: SE ENVIÓ INFORMACIÓN | O20: MOSTRÓ INTERÉS | P20: MOSTRÓ INTERÉS
B21: Alejandro Romero Chu | C21: 902280258 | D21: aberrocal@lnjfg.edu.pe | G21: COMUNICACIONES | H21: PAUTA DIGITAL | I21: SURQUILLO | J21: 2025-II | N21: SE ENVIÓ INFORMACIÓN | O21: MOSTRÓ INTERÉS | P21: MOSTRÓ INTERÉS
B22: Alessandro Braga | C22: 975458726 | D22: lu.vilcg@gmail.com | G22: COMUNICACIONES | H22: PAUTA DIGITAL | I22: SURQUILLO | J22: 2025-II | N22: NO CONTESTA | O22: NO CONTESTA | P22: NO CONTESTA
B23: Bianca Bulic Castillo | C23: 956364110 | D23: ale_virgo596@hotmail.com | G23: COMUNICACIONES | H23: PAUTA DIGITAL | I23: SURQUILLO | J23: 2025-II | N23: NO CONTESTA | O23: NO CONTESTA | P23: NO CONTESTA
B24: Natalia Massiel Gibaja Valle | C24: 934036246 | D24: samirsajs09@gmail.com | G24: COMUNICACIONES | H24: PAUTA DIGITAL | I24: SURQUILLO | J24: 2025-II | N24: SE ENVIÓ INFORMACIÓN | O24: NO CONTESTA | P24: NO CONTESTA
B25: Ericka Mejia Malafaya | C25: 980 199 733 | G25: COMUNICACIONES | H25: PAUTA DIGITAL | I25: SURQUILLO | J25: 2025-II | N25: SE ENVIÓ INFORMACIÓN | O25: NO CONTESTA | P25: NO CONTESTA
B26: Jennifer La Rosa Díaz | C26: 936236347 | D26: arazielvallejo@gmail.com | G26: COMUNICACIONES | H26: PAUTA DIGITAL | I26: SURQUILLO | J26: 2025-II | N26: SE ENVIÓ INFORMACIÓN | O26: NO CONTESTA | P26: NO CONTESTA
B27: Dayraa | C27: 986763600 | D27: digseba345@gmail.com | G27: COMUNICACIONES | H27: PAUTA DIGITAL | I27: SURQUILLO | J27: 2025-II | N27: NO CONTESTA | O27: NO CONTESTA | P27: NO CONTESTA
B28: Adrina Gutierrez | C28: 920652445 | D28: fabianapr1029@gmail.com | G28: COMUNICACIONES | H28: PAUTA DIGITAL | I28: SURQUILLO | J28: 2025-II | N28: NO CONTESTA | O28: NO CONTESTA | P28: NO CONTESTA
A29: 61334034 | B29: NAYARA NAOMI TACZA HUANCA | C29: 941327543 | D29: NAYARANAOMI880@GMAIL.COM | F29: ORDINARIO | G29: COMUNICACIONES | H29: BASE ANTIGUA | I29: SURQUILLO | J29: 2025-II | N29: MOSTRÓ INTERÉS | O29: MOSTRÓ INTERÉS | P29: MOSTRÓ INTERÉS | Q29: NO- VIRTUAL | R29: ADMITIDO | S29: VIRTUAL | T29: RINDIO VIRTUAL | U29: PENDIENTE TODO
A30: 40030211 | B30: Giannina Grados | C30: 51991405952 | D30: gianninagrados@gmail.com | G30: COMUNICACIONES | H30: PAUTA DIGITAL | I30: SURQUILLO | J30: 2025-II | N30: SE ENVIÓ INFORMACIÓN | O30: NO CONTESTA | P30: NO CONTESTA
A31: 75218160 | B31: RENZO SEBASTIAN QQUELLCA LOPEZ | C31: +51 933 748 465 | D31: renzosebastianql@gmail.com | F31: ORDINARIO | G31: COMUNICACIONES | H31: COUNTER | I31: SURQUILLO | J31: 2025-II | N31: MOSTRÓ INTERÉS | O31: MOSTRÓ INTERÉS | P31: MOSTRÓ INTERÉS | Q31: NO- VIRTUAL | R31: ADMITIDO | S31: VIRTUAL | T31: RINDIO VIRTUAL | U31: ENTREGADO-COMPLETO
A32: 60919416 | B32: Santiago Andre Piñas Zumaran | C32: 940266511 | D32: sanpizum13@gmail.com | F32: ORDINARIO | G32: PSICOLOGIA | H32: COUNTER | I32: SURQUILLO | J32: 2025-II | K32: Open Day 3 | L32: Open Day 3 | N32: SE ENVIÓ INFORMACIÓN | O32: SI CONFIRMÓ PARA EL EVENTO | P32: SI CONFIRMÓ PARA EL EVENTO | Q32: NO- VIRTUAL | R32: ADMITIDO | S32: VIRTUAL | T32: RINDIO VIRTUAL | U32: ENTREGADO-COMPLETO
A33: 77807888 | B33: Joseph Díaz Aquino | C33: 971422 058 | D33: josephdiazaquino152@gmail.com | F33: ORDINARIO | G33: COMUNICACIONES | H33: BASE ANTIGUA | I33: SURQUILLO | J33: 2025-II | N33: MOSTRÓ INTERÉS | O33: MOSTRÓ INTERÉS | P33: MOSTRÓ INTERÉS | Q33: NO- VIRTUAL | R33: ADMITIDO | S33: VIRTUAL | T33: RINDIO VIRTUAL | U33: PENDIENTE TODO
A34: 60737299 | B34: Priscila Rosa Ester Avila Rojas | C34: 941140732 | D34: primix0206@gmail.com | F34: ORDINARIO | G34: COMUNICACIONES | H34: BASE ANTIGUA | I34: SURQUILLO | J34: 2025-II | N34: MOSTRÓ INTERÉS | O34: MOSTRÓ INTERÉS | P34: MOSTRÓ INTERÉS | Q34: NO- VIRTUAL | R34: ADMITIDO | S34: VIRTUAL | T34: RINDIO VIRTUAL | U34: ENTREGADO-COMPLETO
A35: 70638960 | B35: Maryorit Alison Vanesa Tutaya linares | C35: 915177778 | D35: maryori.tutaya06@gmail.com | F35: ORDINARIO | G35: TURISMO | H35: BASE ANTIGUA | I35: SURQUILLO | J35: 2025-II | N35: MOSTRÓ INTERÉS | O35: MOSTRÓ INTERÉS | P35: MOSTRÓ INTERÉS | Q35: NO- VIRTUAL | R35: ADMITIDO | S35: VIRTUAL | T35: RINDIO VIRTUAL | U35: PENDIENTE TODO
A36: 70726548 | B36: Danna Patricia Carranza Mesias | C36: 912454673 | D36: danna.carranza1508@gmail.com | F36: ORDINARIO | G36: PSICOLOGIA | H36: BASE ANTIGUA | I36: SURQUILLO | J36: 2025-II | N36: MOSTRÓ INTERÉS | O36: MOSTRÓ INTERÉS | P36: MOSTRÓ INTERÉS | Q36: NO- VIRTUAL | R36: ADMITIDO | S36: VIRTUAL | T36: RINDIO VIRTUAL | U36: PENDIENTE TODO
A37: 71144913 | B37: Romina Flores Medina | C37: 994836 815 | D37: ROMIFLOWERS5@GMAIL.COM | F37: ORDINARIO | G37: COMUNICACIONES | H37: BASE ANTIGUA | I37: SURQUILLO | J37: 2025-II | N37: MOSTRÓ INTERÉS | O37: MOSTRÓ INTERÉS | P37: MOSTRÓ INTERÉS | Q37: NO- VIRTUAL | R37: ADMITIDO | S37: VIRTUAL | T37: RINDIO VIRTUAL | U37: PENDIENTE TODO
A38: 72896294 | B38: Carlos Victor Aaron Tejada Beas | C38: 923 504 852 | D38: aarontejadabeas@gmail.com | F38: ORDINARIO | G38: PSICOLOGIA | H38: BASE ANTIGUA | I38: SURQUILLO | J38: 2025-II | N38: MOSTRÓ INTERÉS | O38: MOSTRÓ INTERÉS | P38: MOSTRÓ INTERÉS | Q38: NO- VIRTUAL | R38: ADMITIDO | S38: VIRTUAL | T38: RINDIO VIRTUAL | U38: PENDIENTE TODO
A39: 71145273 | B39: Flor de Maria Pacheco Patiño | C39: 999365741 | D39: avierorlando15@hotmail.com | F39: ORDINARIO | G39: COMUNICACIONES | H39: BASE ANTIGUA | I39: SURQUILLO | J39: 2025-II | N39: MOSTRÓ INTERÉS | O39: MOSTRÓ INTERÉS | P39: MOSTRÓ INTERÉS | Q39: NO- VIRTUAL | R39: ADMITIDO | S39: VIRTUAL | T39: RINDIO VIRTUAL | U39: PENDIENTE TODO
A40: 62051295 | B40: Sergio Roy Chi Garro | C40: 944331736 | D40: faser2708@gmail.com | F40: ORDINARIO | G40: COMUNICACIONES | H40: BASE ANTIGUA | I40: SURQUILLO | J40: 2025-II | N40: MOSTRÓ INTERÉS | O40: MOSTRÓ INTERÉS | P40: MOSTRÓ INTERÉS | Q40: NO- VIRTUAL | R40: ADMITIDO | S40: VIRTUAL | T40: RINDIO VIRTUAL | U40: ENTREGADO-COMPLETO
...

Sheet BD|Lilya E.
A1: DNI | B1: NOMBRES | C1: CELULAR | D1: CORREO | E1: COLEGIO DE PROCEDENCIA | F1: MODALIDAD | G1: ESCUELA | H1: ORIGEN | I1: SEDE | J1: SEMESTRE | K1: CAMPAÑA | L1: EVENTO | M1: FECHA DE INGRESO DE LEAD | N1: CONTACTO I | O1: CONTACTO II | P1: CONTACTO III | Q1: ¿PAGÓ DERECHO DE INSCRIPCIÓN? | R1: STATUS ACADÉMICO | S1: TIPO DE EXAMEN | T1: STATUS DE EXAMEN | U1: ENTREGA DE DOCUMENTOS | V1: OBSERVACION
A2: 61530615 | B2: Dana | C2: 51934364137 | D2: dana.lossio11@gmail.com | G2: COMUNICACIONES | H2: PAUTA DIGITAL | I2: SURQUILLO | J2: 2025-II | K2: Open Day 2 | L2: Open Day 2 | N2: SE ENVIÓ INFORMACIÓN | P2: =TRIM(BD_LilyaEspinoza[[#This Row],[CONTACTO II]])
A3: 72985252 | B3: luana | C3: 51985464024 | D3: p6eljaraespinoza@gmail.com | G3: COMUNICACIONES | H3: PAUTA DIGITAL | I3: SURQUILLO | J3: 2025-II | K3: Open Day 2 | L3: Open Day 2 | N3: SE ENVIÓ INFORMACIÓN | P3: =TRIM(BD_LilyaEspinoza[[#This Row],[CONTACTO II]])
A4: 10318207 | B4: Angie Barboza (SU HIJO ESTA EN 4 AÑO, SOLO QUIERE INFORMACION) | C4: 51967579172 | D4: angiebarbozabbva@gmail.com | G4: COMUNICACIONES | H4: PAUTA DIGITAL | J4: 2025-II | K4: Open Day 2 | L4: Open Day 2 | N4: MOSTRÓ INTERÉS | O4: SE ENVIÓ INFORMACIÓN | P4: =TRIM(BD_LilyaEspinoza[[#This Row],[CONTACTO II]]) -> SE ENVIÓ INFORMACIÓN
A5: 74433285 | B5: Priscilla Jumachi Ramírez | C5: 51976035113 | D5: jumachiramirezpriscila@gmail.com | E5: TERMINÉ EL COLEGIO | F5: ORDINARIO | G5: COMUNICACIONES | H5: PAUTA DIGITAL | J5: 2025-II | K5: Taller Vivencial 2 | L5: Taller Vivencial 2 | N5: MOSTRÓ INTERÉS | O5: SE ENVIÓ INFORMACIÓN | P5: =TRIM(BD_LilyaEspinoza[[#This Row],[CONTACTO II]]) -> SE ENVIÓ INFORMACIÓN
A6: 44254678 | B6: Yessy Perez Arango | C6: 51952324378 | D6: yessy_perez_1404@hotmail.es | G6: COMUNICACIONES | H6: PAUTA DIGITAL | J6: 2025-II | K6: Open Day 2 | L6: Open Day 2 | N6: MOSTRÓ INTERÉS | P6: =TRIM(BD_LilyaEspinoza[[#This Row],[CONTACTO II]])
A7: 61493469 | B7: Luana Camila Garcia Estrada | C7: 51994919135 | D7: garciaestradaluanacamila@gmail.com | G7: COMUNICACIONES | H7: PAUTA DIGITAL | J7: 2025-II | K7: Open Day 2 | L7: Open Day 2 | N7: MOSTRÓ INTERÉS | P7: =TRIM(BD_LilyaEspinoza[[#This Row],[CONTACTO II]])
A8: 72555167 | B8: Gael Alessandro Mejia Ravelo | C8: 51922744446 | D8: gaelmejrav@gmail.com | G8: COMUNICACIONES | H8: PAUTA DIGITAL | J8: 2025-II | K8: Open Day 2 | L8: Open Day 2 | N8: OTROS | P8: =TRIM(BD_LilyaEspinoza[[#This Row],[CONTACTO II]]) | V8: DERECHO
A9: 41814832 | B9: Miguel Angel Borja Ramirez (su hija esta en 4to) | C9: 51952063649 | D9: angel_miguel5@hotmail.com | G9: COMUNICACIONES | H9: PAUTA DIGITAL | I9: SURQUILLO | J9: 2025-II | K9: Taller Vivencial 2 | N9: SE ENVIÓ INFORMACIÓN
A10: 10707384 | B10: Amalia Rosalia Huamansupa Méndez | C10: 51931663262 | D10: amaliarosalia2@gmail.com | G10: COMUNICACIONES | H10: PAUTA DIGITAL | J10: 2025-II | K10: Taller Vivencial 2 | L10: Taller Vivencial 2 | N10: SE ENVIÓ INFORMACIÓN | P10: =TRIM(BD_LilyaEspinoza[[#This Row],[CONTACTO II]])
A11: 73265708 | B11: VALERIA CELESTE BENDEZU URBINA | C11: 903588607 | D11: VALERIABENDEZU777@GMAIL.COM | E11: termino el colegio | F11: ORDINARIO | G11: COMUNICACIONES | H11: COUNTER | I11: SURQUILLO | J11: 2025-II | N11: MOSTRÓ INTERÉS | O11: MOSTRÓ INTERÉS | P11: =TRIM(BD_LilyaEspinoza[[#This Row],[CONTACTO II]]) -> MOSTRÓ INTERÉS | Q11: NO- VIRTUAL | R11: ADMITIDO | S11: VIRTUAL | T11: RINDIO VIRTUAL
A12: 47464055 | B12: Pool Guillermo Del Valle Chuquichanca | C12: 992419321 | D12: poolguillermodelvalle@gmail.com | E12: TERMINÉ EL COLEGIO | F12: ORDINARIO | G12: COMUNICACIONES | H12: PAUTA DIGITAL | I12: SURQUILLO | J12: 2025-II | N12: MOSTRÓ INTERÉS | O12: MOSTRÓ INTERÉS | P12: =TRIM(BD_LilyaEspinoza[[#This Row],[CONTACTO II]]) -> MOSTRÓ INTERÉS | Q12: NO- VIRTUAL | R12: ADMITIDO | S12: VIRTUAL | T12: RINDIO VIRTUAL
A13: 61294597 | B13: LAURA SOFIA MORALES BOBADILLA | C13: 923162958 | D13: XLAURAMORALESX@GMAIL.COM | E13: TERMINÉ EL COLEGIO | F13: ORDINARIO | G13: COMUNICACIONES | H13: COUNTER | J13: 2025-II | N13: MOSTRÓ INTERÉS | O13: MOSTRÓ INTERÉS | P13: =TRIM(BD_LilyaEspinoza[[#This Row],[CONTACTO II]]) -> MOSTRÓ INTERÉS | Q13: NO- VIRTUAL | R13: ADMITIDO | S13: VIRTUAL | T13: RINDIO VIRTUAL | U13: PENDIENTE TODO
A14: 76093066 | B14: araceli mireya hilario huarcaya | C14: 51922585910 | D14: aracelihilario12@hotmail.com | G14: COMUNICACIONES | H14: PAUTA DIGITAL | I14: SURQUILLO | J14: 2025-II | K14: Taller Vivencial 2 | L14: Taller Vivencial 2 | N14: NO CONTESTA | P14: =TRIM(BD_LilyaEspinoza[[#This Row],[CONTACTO II]])
A15: 9855340 | B15: Jeanett Rojas (busca becas deportivas) | C15: 51990644062 | D15: jeanettrb@hotmail.com | G15: COMUNICACIONES | H15: PAUTA DIGITAL | I15: SURQUILLO | J15: 2025-II | K15: Taller Vivencial 2 | L15: Taller Vivencial 2 | N15: SELECCIONÓ OTRA UNIVERSIDAD | P15: =TRIM(BD_LilyaEspinoza[[#This Row],[CONTACTO II]])
A16: 45513037 | B16: Slingger Mendez Risco (busca modalidad virtual) | C16: 51983076522 | D16: mendezrisco66@gmail.com | G16: COMUNICACIONES | H16: PAUTA DIGITAL | I16: SURQUILLO | J16: 2025-II | K16: Taller Vivencial 2 | L16: Taller Vivencial 2 | N16: SELECCIONÓ OTRA UNIVERSIDAD | P16: =TRIM(BD_LilyaEspinoza[[#This Row],[CONTACTO II]])
B17: Sandra Natalia | C17: 51929906915 | D17: sandranac7@gmail.com | G17: COMUNICACIONES | H17: PAUTA DIGITAL | I17: SURQUILLO | J17: 2025-II | K17: Open Day 1 | L17: Open Day 1 | N17: NO CONTESTA | O17: NO CONTESTA | P17: =TRIM(BD_LilyaEspinoza[[#This Row],[CONTACTO II]]) -> NO CONTESTA
B18: Thais Mendoza Cardenas | C18: 977 370 299 | G18: COMUNICACIONES | H18: PAUTA DIGITAL | I18: SURQUILLO | J18: 2025-II | K18: Open Day 1 | L18: Open Day 1 | N18: NO CONTESTA | O18: NO CONTESTA | P18: =TRIM(BD_LilyaEspinoza[[#This Row],[CONTACTO II]]) -> NO CONTESTA
B19: Tatiana Salazar | C19: 964853500 | D19: josuevsalas.22@gmail.com | G19: COMUNICACIONES | H19: PAUTA DIGITAL | I19: SURQUILLO | J19: 2025-II | K19: Open Day 1 | L19: Open Day 1 | N19: NO CONTESTA | O19: NO CONTESTA | P19: =TRIM(BD_LilyaEspinoza[[#This Row],[CONTACTO II]]) -> NO CONTESTA
B20: Lucy Saire | C20: 961605219 | D20: aquiquijanasalas@gmail.com | G20: COMUNICACIONES | H20: PAUTA DIGITAL | I20: SURQUILLO | J20: 2025-II | K20: Open Day 1 | L20: Open Day 1 | N20: NO CONTESTA | O20: NO CONTESTA | P20: =TRIM(BD_LilyaEspinoza[[#This Row],[CONTACTO II]]) -> NO CONTESTA
A21: 10478909 | B21: Leoncio Manuel Yanac Huamani | C21: 51987774324 | D21: yamashiro999@hotmail.com | G21: COMUNICACIONES | H21: PAUTA DIGITAL | I21: SURQUILLO | J21: 2025-II | K21: Taller Vivencial 2 | L21: Taller Vivencial 2 | N21: NO CONTESTA | P21: =TRIM(BD_LilyaEspinoza[[#This Row],[CONTACTO II]])
B22: Ana Arroyo Paz | C22: 977250157 | D22: angelinacasias0@gmail.com | G22: COMUNICACIONES | H22: PAUTA DIGITAL | I22: SURQUILLO | J22: 2025-II | K22: Open Day 1 | L22: Open Day 1 | N22: NO CONTESTA | O22: NO CONTESTA | P22: =TRIM(BD_LilyaEspinoza[[#This Row],[CONTACTO II]]) -> NO CONTESTA
B23: José Encarnación Mendoza Fiestas | C23: 958804504 | D23: mayorcajosecarlos@gmail.com | G23: COMUNICACIONES | H23: PAUTA DIGITAL | I23: SURQUILLO | J23: 2025-II | K23: Open Day 1 | L23: Open Day 1 | N23: NO CONTESTA | O23: NO CONTESTA | P23: =TRIM(BD_LilyaEspinoza[[#This Row],[CONTACTO II]]) -> NO CONTESTA
A24: 61422059 | B24: Yami Bautista | C24: 51933763900 | D24: yamibauqui@gmail.com | G24: COMUNICACIONES | H24: PAUTA DIGITAL | I24: SURQUILLO | J24: 2025-II | K24: Taller Vivencial 2 | L24: Taller Vivencial 2 | N24: NO CONTESTA | P24: =TRIM(BD_LilyaEspinoza[[#This Row],[CONTACTO II]])
A25: 41500340 | B25: Betsy Janet Alarcon | C25: 51991775318 | D25: betsyalarcon1620@gmail.com | G25: COMUNICACIONES | H25: PAUTA DIGITAL | I25: SURQUILLO | J25: 2025-II | K25: Taller Vivencial 2 | L25: Taller Vivencial 2 | N25: INCONTACTABLE | P25: =TRIM(BD_LilyaEspinoza[[#This Row],[CONTACTO II]])
A26: 45510408 | B26: Omar Alayo M | C26: 51981283728 | D26: omaralayo.contacto@gmail.com | G26: COMUNICACIONES | H26: PAUTA DIGITAL | I26: SURQUILLO | J26: 2025-II | K26: Taller Vivencial 2 | L26: Taller Vivencial 2 | N26: SE ENVIÓ INFORMACIÓN | P26: =TRIM(BD_LilyaEspinoza[[#This Row],[CONTACTO II]])
A27: 71151536 | B27: FABIAN ARTURO MELENDEZ ARIZAGA | C27: 949141024 | D27: fabianmcu@gmail.com | E27: TERMINÉ EL COLEGIO | F27: ORDINARIO | G27: COMUNICACIONES | H27: BASE ANTIGUA | J27: 2025-II | N27: MOSTRÓ INTERÉS | O27: MOSTRÓ INTERÉS | P27: =TRIM(BD_LilyaEspinoza[[#This Row],[CONTACTO II]]) -> MOSTRÓ INTERÉS | Q27: NO- VIRTUAL | R27: ADMITIDO | S27: VIRTUAL | T27: RINDIO VIRTUAL
A28: 72984417 | B28: CHIARA CASAPIA MONTENEGRO | C28: 976544471 | D28: CHIARACASAPIAM@GMAIL.COM | G28: COMUNICACIONES | H28: EVENTO PRESENCIAL | I28: SANTA ANITA | J28: 2025-II | N28: MOSTRÓ INTERÉS | P28: =TRIM(BD_LilyaEspinoza[[#This Row],[CONTACTO II]])
A29: 78719582 | B29: VICTOR RICARDO ARENAS HAUCASE | C29: 974339475 | D29: lesliearenas29@gmail.com | G29: PSICOLOGIA | H29: EVENTO PRESENCIAL | I29: SURQUILLO | J29: 2025-II | N29: MOSTRÓ INTERÉS | O29: SE ENVIÓ INFORMACIÓN | P29: =TRIM(BD_LilyaEspinoza[[#This Row],[CONTACTO II]]) -> SE ENVIÓ INFORMACIÓN
A30: 71166102 | B30: Xiomara Aime Peña Cahuama | C30: 927306453 | D30: Xiomaraaime15@gmail.com | G30: PSICOLOGIA | H30: EVENTO PRESENCIAL | I30: SURQUILLO | J30: 2025-II | N30: NO CONTESTA | O30: NO CONTESTA | P30: =TRIM(BD_LilyaEspinoza[[#This Row],[CONTACTO II]]) -> NO CONTESTA
A31: 70951357 | B31: Emilio Silva Molina | C31: 915 950 336 | D31: emiliosilvamolina@gmail.com | G31: TURISMO | H31: EVENTO PRESENCIAL | I31: SURQUILLO | J31: 2025-II | N31: SELECCIONÓ OTRA UNIVERSIDAD | O31: NO CONTESTA | P31: =TRIM(BD_LilyaEspinoza[[#This Row],[CONTACTO II]]) -> NO CONTESTA
A32: 75483496 | B32: Jasmin Chavez | C32: 990193900 | D32: jasminchavezkj@gmail.com | G32: COMUNICACIONES | H32: EVENTO PRESENCIAL | I32: SURQUILLO | J32: 2025-II | N32: NO CONTESTA | O32: NO CONTESTA | P32: =TRIM(BD_LilyaEspinoza[[#This Row],[CONTACTO II]]) -> NO CONTESTA
A33: 70622193 | B33: Aylin Escalante | C33: 51994840331 | D33: ailynescalantenoa@gmail.com | G33: PSICOLOGIA | H33: EVENTO PRESENCIAL | I33: SURQUILLO | J33: 2025-II | N33: NO CONTESTA | O33: NO CONTESTA | P33: =TRIM(BD_LilyaEspinoza[[#This Row],[CONTACTO II]]) -> NO CONTESTA
A34: 73537627 | B34: Adriana Huaringa | C34: 51989837748 | D34: adrianitah.1718@gmail.com | G34: PSICOLOGIA | H34: EVENTO PRESENCIAL | I34: SURQUILLO | J34: 2025-II | N34: NO CONTESTA | O34: NO CONTESTA | P34: =TRIM(BD_LilyaEspinoza[[#This Row],[CONTACTO II]]) -> NO CONTESTA
A35: 71188577 | B35: Fabian Sandi Malca | C35: 51931530179 | D35: fabiansandimalca@gmail.com | G35: PSICOLOGIA | H35: EVENTO PRESENCIAL | I35: SURQUILLO | J35: 2025-II | N35: OTROS | O35: NO CONTESTA | P35: =TRIM(BD_LilyaEspinoza[[#This Row],[CONTACTO II]]) -> NO CONTESTA | V35: PROVINCIA
A36: 61294582 | B36: Génesis Sarmiento solis | C36: 51977150446 | D36: genesismiacielo12@gmail.com | G36: COMUNICACIONES | H36: EVENTO PRESENCIAL | I36: SURQUILLO | J36: 2025-II | N36: NO CONTESTA | O36: NO CONTESTA | P36: =TRIM(BD_LilyaEspinoza[[#This Row],[CONTACTO II]]) -> NO CONTESTA
A37: 72328397 | B37: Jansel Raul Muñoz Macedo | C37: 926286360 | D37: jhans.1807@gmail.com | E37: CIBERTEC | F37: ORDINARIO | G37: PSICOLOGIA | H37: EVENTO PRESENCIAL | I37: SANTA ANITA | J37: 2025-II | N37: MOSTRÓ INTERÉS | O37: SE ENVIÓ INFORMACIÓN | P37: =TRIM(BD_LilyaEspinoza[[#This Row],[CONTACTO II]]) -> SE ENVIÓ INFORMACIÓN | Q37: NO- VIRTUAL | R37: ADMITIDO | S37: VIRTUAL | T37: RINDIO VIRTUAL | U37: PEND. CERTIFICADO
A38: 76299118 | B38: Keyco Celina Mt | C38: 51970927314 | D38: keyco.a20@gmail.com | G38: PSICOLOGIA | H38: EVENTO PRESENCIAL | I38: SURQUILLO | J38: 2025-II | N38: INCONTACTABLE | O38: MOSTRÓ INTERÉS | P38: SE ENVIÓ INFORMACIÓN
A39: 76390529 | B39: Alexia Perla | C39: 51997054491 | D39: perlayauriantonio@gmail.com | G39: PSICOLOGIA | H39: EVENTO PRESENCIAL | I39: SURQUILLO | J39: 2025-II | N39: NO CONTESTA | O39: NO CONTESTA | P39: =TRIM(BD_LilyaEspinoza[[#This Row],[CONTACTO II]]) -> NO CONTESTA
A40: 76320818 | B40: Flavio Castro Chalo | C40: 948287087 | D40: flaviocastrochalo4@gmail.com | G40: PSICOLOGIA | H40: EVENTO PRESENCIAL | I40: SURQUILLO | J40: 2025-II | N40: INCONTACTABLE | O40: INCONTACTABLE | P40: =TRIM(BD_LilyaEspinoza[[#This Row],[CONTACTO II]]) -> INCONTACTABLE
...

Sheet BD|Sheyla P.
A1: DNI | B1: NOMBRES | C1: CELULAR | D1: CORREO | E1: COLEGIO DE PROCEDENCIA | F1: MODALIDAD | G1: ESCUELA | H1: ORIGEN | I1: SEDE | J1: SEMESTRE | K1: CAMPAÑA | L1: EVENTO | M1: FECHA DE INGRESO DE LEAD | N1: CONTACTO I | O1: CONTACTO II | P1: CONTACTO III | Q1: ¿PAGÓ DERECHO DE INSCRIPCIÓN? | R1: STATUS ACADÉMICO | S1: TIPO DE EXAMEN | T1: STATUS DE EXAMEN | U1: ENTREGA DE DOCUMENTOS | V1: OBSERVACION
A2: 71192234 | B2: Piero Eduardo Garibotto Cuervas | C2: 943274989 | G2: PSICOLOGIA | L2: Open Day 3 | M2: 45880
A3: 74919051 | B3: Carlos Rubén Gutiérrez Silva | C3: 947764639 | L3: Open Day 3 | M3: 45880 | N3: MOSTRÓ INTERÉS | O3: MOSTRÓ INTERÉS | P3: SI CONFIRMÓ PARA EL EVENTO | Q3: NO - VIRTUAL | R3: INSCRITO | S3: VIRTUAL | T3: RENDIRA VIRTUAL | U3: PENDIENTE TODO | V3: examen agendado
C4: 973 814 991 | E4: 2da carrera | G4: TURISMO | L4: Open Day 3 | M4: 45880 | N4: MOSTRÓ INTERÉS | O4: MOSTRÓ INTERÉS | P4: MOSTRÓ INTERÉS
B5: AMBULAY LOPEZ JAEL | C5: 932340545 | G5: PSICOLOGIA | H5: VISITA A COLEGIOS | L5: Open Day 3 | M5: 45880 | N5: SE ENVIÓ INFORMACIÓN
A6: 61454141 | B6: GUZMAN FLORES JOAQUIN ALFONSO | C6: 920691058 | G6: TURISMO | H6: VISITA A COLEGIOS | L6: Open Day 3 | M6: 45880 | N6: SE ENVIÓ INFORMACIÓN
A7: 72062571 | B7: QUEVEDO AYARZA SOFIA | C7: 986694205 | G7: PSICOLOGIA | H7: VISITA A COLEGIOS | L7: Open Day 3 | M7: 45880 | N7: SE ENVIÓ INFORMACIÓN | O7: MOSTRÓ INTERÉS | P7: SI CONFIRMÓ PARA EL EVENTO | V7: primera opc. derecho
B8: Enrique | C8: 931 277 290 | L8: Open Day 3 | M8: 45880 | N8: SE ENVIÓ INFORMACIÓN
A9: 60934639 | B9: Tadeo Chaupis Acevedo | C9: 991279767 | D9: cyntty3@hotmail.com | F9: ORDINARIO | G9: PSICOLOGIA | H9: PAUTA DIGITAL | L9: Open Day 3 | M9: 45877 | N9: MOSTRÓ INTERÉS | O9: MOSTRÓ INTERÉS | P9: MOSTRÓ INTERÉS | Q9: NO - VIRTUAL | R9: INSCRITO | S9: VIRTUAL | T9: RENDIRA VIRTUAL | U9: PENDIENTE TODO | V9: examen agendado
A10: 73185903 | B10: Danitza Díaz | C10: 951 077 597 | G10: PSICOLOGIA | H10: COUNTER | L10: Open Day 3 | M10: 45876 | N10: MOSTRÓ INTERÉS | O10: MOSTRÓ INTERÉS | P10: SI CONFIRMÓ PARA EL EVENTO
A11: 61330183 | B11: Fiorella Herrera García | C11: 968042118 | G11: COMUNICACIONES | H11: WEB | L11: Open Day 3 | M11: 45877 | N11: SE ENVIÓ INFORMACIÓN
A12: 72591161 | B12: ROJAS CALLAHUI KENDRA NICOLE | C12: 908502802 | G12: PSICOLOGIA | H12: COUNTER | L12: Open Day 3 | M12: 45876 | N12: MOSTRÓ INTERÉS | O12: MOSTRÓ INTERÉS | P12: MOSTRÓ INTERÉS | Q12: NO - VIRTUAL | R12: ADMITIDO | S12: VIRTUAL | T12: RINDIO VIRTUAL | U12: PENDIENTE TODO
A13: 73153352 | B13: Angelina Milagros Chavez Lino | C13: 904386445 | G13: COMUNICACIONES | H13: COUNTER | L13: Open Day 3 | M13: 45876 | N13: MOSTRÓ INTERÉS | O13: MOSTRÓ INTERÉS | P13: SI CONFIRMÓ PARA EL EVENTO | V13: dio examen en jpckey
A14: 61507953 | B14: JUAN MANUEL DEL AGUILA TELLO | C14: 972 121 263 | G14: TURISMO | H14: WEB | L14: Open Day 3 | M14: 45874 | N14: SE ENVIÓ INFORMACIÓN | O14: NO HUBO PROGRESO | P14: NO HUBO PROGRESO | V14: no es de lima. llega en oct
A15: 61179579 | B15: Luciana Macarena Campos Luque | C15: 918 536 943 | F15: ORDINARIO | L15: Open Day 3 | M15: 45874 | N15: SE ENVIÓ INFORMACIÓN | O15: MOSTRÓ INTERÉS | P15: MOSTRÓ INTERÉS
C16: 973 814 991 | G16: TURISMO | H16: COUNTER | L16: Open Day 3 | M16: 45870 | N16: SE ENVIÓ INFORMACIÓN | O16: NO CONTESTA
A17: 61355150 | B17: Carmen Lucia Domínguez Chávez | C17: 918134943 | F17: CEA | G17: PSICOLOGIA | H17: PAUTA DIGITAL | I17: SURQUILLO | L17: Open Day 3 | M17: 45870 | N17: MOSTRÓ INTERÉS | O17: MOSTRÓ INTERÉS | P17: MOSTRÓ INTERÉS | Q17: NO - VIRTUAL | R17: ADMITIDO | S17: VIRTUAL | T17: RINDIO VIRTUAL | U17: PENDIENTE TODO
A18: 72839888 | B18: Ariana Antezana | C18: 902298310 | F18: ORDINARIO | G18: PSICOLOGIA | H18: COUNTER | I18: SURQUILLO | L18: Open Day 3 | M18: 45870 | N18: SE ENVIÓ INFORMACIÓN | O18: MOSTRÓ INTERÉS
A19: 71364379 | B19: Luciana Herrada Blanco | C19: 963067320 | F19: ORDINARIO | G19: PSICOLOGIA | H19: COUNTER | L19: Open Day 3 | M19: 45870 | N19: MOSTRÓ INTERÉS | O19: MOSTRÓ INTERÉS | P19: SI CONFIRMÓ PARA EL EVENTO
A20: 73280134 | B20: Regina Sofía Alcántara Cueva | C20: 934629374 | D20: karinacueva0@gmail.com | F20: PRIMERA ALTERNATIVA | G20: PSICOLOGIA | H20: COUNTER | I20: COMAS | L20: Open Day 3 | M20: 45869 | N20: MOSTRÓ INTERÉS | O20: MOSTRÓ INTERÉS | P20: SI CONFIRMÓ PARA EL EVENTO | Q20: NO - VIRTUAL | R20: ADMITIDO | S20: VIRTUAL | T20: RINDIO VIRTUAL | U20: PENDIENTE TODO
A21: 71155955 | B21: Alex Fernando Gonzales Alvarado | C21: 913148015 | D21: pedritogonzales80@gmail.com | E21: 973 814 991 | G21: PSICOLOGIA | H21: COUNTER | L21: Open Day 3 | M21: 45869 | N21: SE ENVIÓ INFORMACIÓN | O21: NO CONTESTA
C22: 983 323 640 | G22: PSICOLOGIA | L22: Taller Vivencial 3 | N22: SE ENVIÓ INFORMACIÓN
B23: Richard Josue Parra Muñoz | C23: 952826055 | F23: ORDINARIO | G23: COMUNICACIONES | H23: COUNTER | N23: SE ENVIÓ INFORMACIÓN
A25: 61845695 | B25: camila crisanto basurto | C25: 979439393 | G25: PSICOLOGIA | L25: Taller Vivencial 3 | N25: INCONTACTABLE | O25: INCONTACTABLE | P25: INCONTACTABLE
A26: 61506496 | B26: margiori cabrera adrian | C26: 954251630 | F26: PA | G26: PSICOLOGIA | H26: COUNTER | L26: Taller Vivencial 3 | N26: MOSTRÓ INTERÉS | O26: MOSTRÓ INTERÉS | P26: MOSTRÓ INTERÉS | Q26: NO - VIRTUAL | R26: INSCRITO | S26: VIRTUAL | T26: RENDIRA VIRTUAL | U26: PENDIENTE TODO | V26: Generado en sta anita con quivocacion, desea surquillo
A27: 72068503 | B27: Renata Cristina Chávez Musayon | C27: 945464773 | D27: renatachavezmusayon@gmail.com | G27: COMUNICACIONES | H27: PAUTA DIGITAL | L27: Taller Vivencial 3 | N27: SE ENVIÓ INFORMACIÓN
A28: 70099277 | B28: jonny ashley quezada barboza | C28: 903176498 | F28: ORDINARIO | G28: PSICOLOGIA | H28: COUNTER | I28: LIMA | M28: 45853 | N28: =TRIM(BD_PyaPinto[[#This Row],[CONTACTO II]]) -> SI CONFIRMÓ PARA EL EVENTO | O28: =TRIM(BD_PyaPinto[[#This Row],[CONTACTO II]]) -> SI CONFIRMÓ PARA EL EVENTO | Q28: NO - VIRTUAL | R28: ADMITIDO | S28: VIRTUAL | T28: RINDIO VIRTUAL | U28: PENDIENTE TODO
A29: 42375540 | B29: Marco Antonio Jesus Avila Chavez | C29: 993165586 | F29: ORDINARIO | G29: COMUNICACIONES | H29: COUNTER | L29: Taller Vivencial 3 | M29: 45853 | N29: =TRIM(BD_PyaPinto[[#This Row],[CONTACTO II]]) -> NO CONTESTA | O29: =TRIM(BD_PyaPinto[[#This Row],[CONTACTO II]]) -> NO CONTESTA
A30: 70731653 | B30: Adriano Sanchez Muñoz | C30: 948520404 | E30: terminé_el_colegio | F30: ORDINARIO | G30: COMUNICACIONES | H30: COUNTER | L30: Taller Vivencial 3 | M30: 45852 | N30: =TRIM(BD_PyaPinto[[#This Row],[CONTACTO II]]) -> MOSTRÓ INTERÉS | O30: =TRIM(BD_PyaPinto[[#This Row],[CONTACTO II]]) -> MOSTRÓ INTERÉS | Q30: NO - VIRTUAL | R30: ADMITIDO | S30: VIRTUAL | T30: RINDIO VIRTUAL | U30: PENDIENTE TODO
B31: LUANA FERNANDA CORONEL ARIAS | C31: 983139506 | D31: 4TO SEC | H31: EVENTO PRESENCIAL | L31: Taller Vivencial 3 | M31: 45849 | N31: SE ENVIÓ INFORMACIÓN
B32: MARCO ANTONIO VELARDE SANTA CRUZ | C32: 999341285 | H32: EVENTO PRESENCIAL | J32: 2026-I | M32: 45849 | N32: INCONTACTABLE
A33: 61472194 | B33: PINTO YACTAYO LUCIANO ANDRE | C33: 966167041 | F33: CEA | G33: COMUNICACIONES | H33: COUNTER | L33: Taller Vivencial 3 | M33: 45848 | N33: MOSTRÓ INTERÉS | O33: MOSTRÓ INTERÉS | Q33: NO - VIRTUAL | R33: ADMITIDO | S33: VIRTUAL | T33: RINDIO VIRTUAL | U33: PENDIENTE TODO
A34: 72269404 | B34: Anabel Geraldine Magallanes Vega | C34: 953352104 | F34: ORDINARIO | G34: PSICOLOGIA | H34: COUNTER | I34: LIMA | M34: 45848 | N34: MOSTRÓ INTERÉS | O34: MOSTRÓ INTERÉS | Q34: NO - VIRTUAL | R34: ADMITIDO | S34: VIRTUAL | T34: RINDIO VIRTUAL | U34: PENDIENTE TODO
A35: 0.8195499 | B35: Daniel Cornejo Marsano | C35: 935177607 | G35: COMUNICACIONES | H35: COUNTER | J35: 2026-I | L35: Taller Vivencial 3 | N35: MOSTRÓ INTERÉS
A36: 72704004 | B36: Claudia Ximena Salazar Herrera | C36: 960933725 | D36: clau_xime_01@hotmail.com | G36: COMUNICACIONES | H36: PAUTA DIGITAL | J36: 2025-II | K36: Taller Vivencial 2 | L36: Taller Vivencial 3 | N36: NO CONTESTA
A37: 77524572 | B37: April Mill Julca yaranga | C37: 954741421 | D37: apriljulca7@gmail.com | F37: ORDINARIO | G37: COMUNICACIONES | H37: BASE ANTIGUA | I37: SURQUILLO | J37: 2025-II | L37: Taller Vivencial 3 | N37: MOSTRÓ INTERÉS | O37: MOSTRÓ INTERÉS | Q37: NO- VIRTUAL | R37: ADMITIDO | S37: VIRTUAL | T37: RINDIO VIRTUAL | U37: ENTREGADO-COMPLETO
A38: 77804413 | B38: Antonella Ramos Lopez | C38: 944549724 | D38: anto_754@hotmail.com | F38: ORDINARIO | G38: COMUNICACIONES | H38: BASE ANTIGUA | I38: SURQUILLO | J38: 2025-II | L38: Taller Vivencial 3 | N38: MOSTRÓ INTERÉS | O38: MOSTRÓ INTERÉS | Q38: SÍ- EXAMEN PRESENCIAL | R38: INSCRITO | S38: PRESENCIAL | T38: RENDIRÁ PRESENCIAL | U38: PENDIENTE TODO
A39: 7525972 | B39: Eliana Espejo Romero | C39: 951233434 | D39: zoilipe17@gmail.com | G39: COMUNICACIONES | H39: EVENTO PRESENCIAL | J39: 2025-II | L39: Taller Vivencial 3 | N39: NO CONTESTA
A40: 72421499 | B40: Angie Darlene Panta Rodriguez(mamá) | C40: 934092100 | D40: angie369momo@gmail.com | G40: COMUNICACIONES | H40: EVENTO PRESENCIAL | J40: 2025-II | L40: Taller Vivencial 3 | N40: NO CONTESTA
B41: edu(INTERES POR OTRA DERECHO) | C41: 918826973 | D41: reydelmar2026@gmail.com | F41: TRASLADO EXTERNO | G41: COMUNICACIONES | H41: PAUTA DIGITAL | I41: instituto | J41: 2025-II | L41: Taller Vivencial 3 | N41: NO CONTESTA
...

Sheet BD|Estrella V.
A1: DNI | B1: NOMBRES | C1: CELULAR | D1: CORREO | E1: COLEGIO DE PROCEDENCIA | F1: MODALIDAD | G1: ESCUELA | H1: ORIGEN | I1: SEDE | J1: SEMESTRE | K1: CAMPAÑA | L1: EVENTO | M1: FECHA DE INGRESO DE LEAD | N1: CONTACTO I | O1: CONTACTO II | P1: CONTACTO III | Q1: ¿PAGÓ DERECHO DE INSCRIPCIÓN? | R1: STATUS ACADÉMICO | S1: TIPO DE EXAMEN | T1: STATUS DE EXAMEN | U1: ENTREGA DE DOCUMENTOS | V1: OBSERVACION
A2: 70190769 | B2: Gressi Bernal | C2: 946509653 | D2: gressi.bernal7@outlook.com | G2: PSICOLOGIA | H2: EVENTO PRESENCIAL | I2: SURQUILLO | J2: 2025-II | N2: NO CONTESTA | O2: NO CONTESTA
A3: 4481897 | B3: Gabriela Carrasco | C3: 958372223 | D3: gcc.gaela@gmail.com | G3: COMUNICACIONES | H3: EVENTO PRESENCIAL | I3: SURQUILLO | J3: 2025-II | N3: MOSTRÓ INTERÉS | P3: =TRIM(BD_EstrellaVergara[[#This Row],[CONTACTO II]])
A4: 71977585 | B4: Kriz Figueroa | C4: 980709093 | D4: cristtina.figueroa@hotmail.com | G4: PSICOLOGIA | H4: EVENTO PRESENCIAL | I4: SURQUILLO | J4: 2025-II | N4: NO CONTESTA | O4: NO CONTESTA
A5: 61045287 | B5: Gianella liz Ccahuana Muñoz | C5: 977412641 | D5: gianellaliz12@gmail.com | G5: COMUNICACIONES | H5: EVENTO PRESENCIAL | I5: SURQUILLO | J5: 2025-II | N5: NO CONTESTA | P5: =TRIM(BD_EstrellaVergara[[#This Row],[CONTACTO II]])
A6: 93741783 | B6: Calet Barriga | C6: 966124384 | D6: caletbaldiviezo@gmail.com | G6: PSICOLOGIA | H6: EVENTO PRESENCIAL | I6: SURQUILLO | J6: 2025-II | N6: NO CONTESTA | O6: NO CONTESTA
A7: 61213274 | B7: Ale Herrera | C7: 964664077 | D7: ale1607herrera@gmail.com | G7: PSICOLOGIA | H7: EVENTO PRESENCIAL | I7: SURQUILLO | J7: 2025-II | N7: NO CONTESTA | O7: NO CONTESTA
A8: 74329437 | B8: Sheyla Guillen | C8: 921043308 | D8: sheyla31guillen@gmail.com | G8: PSICOLOGIA | H8: EVENTO PRESENCIAL | I8: SURQUILLO | J8: 2025-II | N8: NO CONTESTA | O8: NO CONTESTA
A9: 77299959 | B9: Sch Yosi | C9: 918295415 | D9: sucachuctayanashiayosi@gmail.com | G9: PSICOLOGIA | H9: EVENTO PRESENCIAL | I9: SURQUILLO | J9: 2025-II | N9: INCONTACTABLE | O9: NO CONTESTA
A10: 21139947 | B10: JANNET LILIA | C10: 999333701 | D10: gut_1977@hotmail.com | G10: COMUNICACIONES | H10: EVENTO PRESENCIAL | I10: SURQUILLO | J10: 2025-II | N10: MOSTRÓ INTERÉS | P10: =TRIM(BD_EstrellaVergara[[#This Row],[CONTACTO II]])
A11: 72674597 | B11: Nayeli Saavedra | C11: 993813827 | D11: Sonrielealavida100pre@gmail.com | G11: COMUNICACIONES | H11: EVENTO PRESENCIAL | I11: SURQUILLO | J11: 2025-II | N11: MOSTRÓ INTERÉS | P11: =TRIM(BD_EstrellaVergara[[#This Row],[CONTACTO II]])
